Workbook
Name IQ_CH: 110000
Name IQ_CQ: 5000
Name IQ_CY: 10000
Name IQ_DAILY: 500000
Name IQ_FH: 100000
Name IQ_FQ: 500
Name IQ_FY: 1000
Name IQ_LTM: 2000
Name IQ_MONTH: 15000
Name IQ_NTM: 6000
Name IQ_WEEK: 50000
Name IQ_YTD: 3000

Sheet SystemsList
B1: *Click on system name to go to the sheet
A2: No. of fields | B2: *Systems List | C2: Hosted in RAKBANK? Can Data be fetched through Databricks or Can be exposed via API? | D2: Appln type | E2: Vendor | F2: Vendor Spoc | G2: Vendor contact | H2: Phone | I2: Technology Owner | J2: Engineering SME | K2: PM | L2: BA | M2: Architect | N2: Technology owner lead | O2: Application link | P2: Remarks
A3: 1184 | B3: Finacle | C3: In Data Platform Scope | D3: ThirdParty | E3: Infosys | F3: Amruta Anil Wadke | G3: Amruta.Wadke@rakbank.ae | I3: Mani John | J3: Sathiyan Venkatesh | N3: Sumat Kumar
A4: 335 | B4: Prime | C4: In Data Platform Scope | D4: ThirdParty | E4: TSYS | F4: Mohamed Sukkari Muhammed Ajmal | G4: mohamedsukkari@tsys.com majmal@tsys.com | H4: (050) 2100680 | I4: Sree Rasmi Shaik Hussain Shariff | J4: Shaik Hussain Shariff | L4: Kanhai Kumar Jha | M4: Ravish Kumar | N4: Gavin Stead
A5: 197 | B5: WMS | C5: In Data Platform Scope | D5: ThirdParty | E5: Infosys | F5: Aditya Kulkarni | G5: Aditya.Kulkarni@rakbank.ae | I5: Mani John | J5: Sathiyan Venkatesh | N5: Sumat Kumar
A6: 190 | B6: RLS | C6: In Data Platform Scope | D6: ThirdParty | E6: Nucleus Software | F6: Kaushal.misra@nucleussoftware.com | G6: Kaushal.misra@nucleussoftware.com | H6: 0091 9810617822 | I6: Mani John | J6: Sathiyan Venkatesh | N6: Sumat Kumar
A7: 74 | B7: CASMEX | C7: In Data Platform Scope | D7: ThirdParty | E7: Distinct Infotech | F7: rajeshkumar.rn@distinctinfotech.com chacko@distinctinfotech.com | G7: rajeshkumar.rn@distinctinfotech.com chacko@distinctinfotech.com | I7: Guruprasad Narayan Shetty | J7: Sathiyan Venkatesh | N7: Sumat Kumar
A8: 73 | B8: IDD | D8: Internal | E8: NA | F8: NA | G8: NA | I8: Gaurav Kumar | J8: Sathiyan Venkatesh | N8: Sumat Kumar
A9: 64 | B9: ICCS - Cheque Flow System | C9: In Data Platform Scope | D9: ThirdParty | E9: NewGen technologies | F9: Anshu Raj | G9: anshu.raj@newgensoft.com | H9: 0091 9971211909 | I9: Guruprasad Narayan Shetty | J9: Sathiyan Venkatesh | N9: Sumat Kumar
A10: 48 | B10: Previous RAKNet Version (Personal Banking) | D10: Internal | E10: NA | F10: NA | G10: NA | I10: Gaurav Kumar | J10: Sathiyan Venkatesh | N10: Sumat Kumar
A11: 48 | B11: Digital Banking Admin | C11: In Data Platform Scope | D11: ThirdParty | E11: Infosys | F11: Saranya | G11: @Saranya Devi Sankarappan (Ext) | I11: Milind Harichandra Gowari | J11: Sathiyan Venkatesh | N11: Lalit Lekhwani
A12: 41 | B12: Pay Hub Plus (NPSS Unity) | D12: ThirdParty | E12: Unity | F12: Veena Vijayan | G12: Veena.Kochattil@rakbank.ae | I12: Guruprasad Narayan Shetty | J12: Sathiyan Venkatesh | N12: Sumat Kumar
A13: 33 | B13: CCM | D13: ThirdParty | E13: Dtech | F13: Muhammed Anees | G13: Muhammed.anees@dtechsoft.com | H13: (054) 4922546 | I13: Mani John | J13: Sathiyan Venkatesh | N13: Sumat Kumar
A14: 32 | B14: CPF | C14: In Data Platform Scope | D14: Internal | E14: NA | F14: NA | G14: NA | I14: Mani John | J14: Sathiyan Venkatesh | N14: Sumat Kumar
A15: 31 | B15: RAKRewards Admin | D15: ThirdParty | E15: ICC | F15: ayush@iccfze.com abhilasha@iccfze.com | G15: ayush@iccfze.com abhilasha@iccfze.com | H15: +971-52-8059072 | I15: Gaurav Kumar | J15: Sathiyan Venkatesh | L15: Kanhai Kumar Jha | M15: Ravish Kumar | N15: Sumat Kumar
A16: 29 | B16: Bank Auth Representative E-Register(auth rep) | D16: Internal | E16: NA | F16: NA | G16: NA | I16: Gaurav Kumar | J16: Sathiyan Venkatesh | N16: Sumat Kumar | O16: Need to check application name
A17: 27 | B17: MDES (PRIME) | D17: ThirdParty | E17: Not Identified
A18: 25 | B18: Cheque Book System | D18: Internal | E18: NA | F18: NA | G18: NA | I18: Gaurav Kumar | J18: Sathiyan Venkatesh | N18: Sumat Kumar
A19: 25 | B19: Cross Sell | D19: ThirdParty | E19: pennanttech | F19: prasad.s@pennanttech.com venkatesh.ch@pennanttech.com | G19: prasad.s@pennanttech.com venkatesh.ch@pennanttech.com | H19: Prasad -917893940697 Venkatesh - 916305949549 | I19: Balaji Natarajan | J19: ? | N19: Sumat Kumar
A20: 24 | B20: Intellect Collection | C20: In Data Platform Scope | D20: ThirdParty | E20: Intellect Design | F20: mallikarjuna.chevvu@intellectdesign.com chelliah.p@intellectdesign.com | G20: mallikarjuna.chevvu@intellectdesign.com chelliah.p@intellectdesign.com | H20: =91-8939838656 -> -8939838565 | I20: Mani John | J20: Sathiyan Venkatesh | N20: Sumat Kumar
A21: 22 | B21: Digital ON-Boarding Tracking (DEH) | C21: In Data Platform Scope | D21: ThirdParty | E21: Infosys | F21: Ayesha Siddikha | G21: @Ayesha Siddikha Mohamed Iqbal (Ext) | I21: Milind Harichandra Gowari | J21: Sathiyan Venkatesh | N21: Lalit Lekhwani
A22: 20 | B22: CPPS | C22: In Data Platform Scope | D22: Internal | E22: NA | F22: NA | G22: NA | I22: Sree Rasmi Shaik Hussain Shariff | J22: Shaik Hussain Shariff | L22: Kanhai Kumar Jha | M22: Ravish Kumar | N22: Gavin Stead
A23: 16 | B23: VISA Online | D23: ThirdParty | E23: Not Identified
A24: 16 | B24: RAKTRACK | D24: ThirdParty | E24: Game Change | F24: Shailesh Tiwari | G24: shailesh.tiwari@gamechangesns.com | H24: (050) 4595618 | I24: Mani John | J24: Sathiyan Venkatesh | N24: Sumat Kumar
A25: 14 | B25: 3D Secure | D25: ThirdParty/Internal | E25: Broadcom | F25: Konrad Karczmarczyk | G25: konrad.karczmarczyk@broadcom.com | I25: Guruprasad Narayan Shetty | J25: Sathiyan Venkatesh | N25: Sumat Kumar
A26: 13 | B26: Team Express Portal | C26: External systems. Data cannot be ingested and can be fetched through API | D26: ThirdParty | E26: Team Express | I26: Mahesh Kannan | J26: Mahesh Kannan | N26: Mahes Kannan
A27: 11 | B27: Infobip | C27: External systems. Data cannot be ingested and can be fetched through API | D27: ThirdParty | E27: Infobip | F27: Edita Rokša Durić <edita.roksaduric@infobip.com>; Neira Kratovac Akriche <neira.kratovacakriche@infobip.com>; Nedžad Grizović <nedzad.grizovic@infobip.com> | G27: Edita Rokša Durić <edita.roksaduric@infobip.com>; Neira Kratovac Akriche <neira.kratovacakriche@infobip.com>; Nedžad Grizović <nedzad.grizovic@infobip.com> | I27: Mani John | J27: Sathiyan Venkatesh | N27: Sumat Kumar
A28: 10 | B28: IBPS | C28: In Data Platform Scope | D28: ThirdParty | E28: NewGen technologies | F28: Anshu Raj | G28: anshu.raj@newgensoft.com | H28: 0091 9971211909 | I28: Gaurav Kumar | J28: Sathiyan Venkatesh | N28: Sumat Kumar
A29: 10 | B29: Prospect | D29: Internal | E29: NA | F29: NA | G29: NA | I29: Gaurav Kumar | J29: Sathiyan Venkatesh | N29: Sumat Kumar
A30: 9 | B30: CardNet | D30: Internal | E30: NA | F30: NA | G30: NA | I30: Sree Rasmi Shaik Hussain Shariff | J30: Shaik Hussain Shariff | N30: Sumat Kumar
A31: 8 | B31: VAT | D31: Internal | E31: NA | F31: NA | G31: NA | I31: Gaurav Kumar | J31: Sathiyan Venkatesh | N31: Sumat Kumar
A32: 7 | B32: CAPS | C32: In Data Platform Scope | D32: Internal | E32: NA | F32: NA | G32: NA | I32: Sree Rasmi Shaik Hussain Shariff | J32: Sathiyan Venkatesh | L32: Kanhai Kumar Jha | M32: Ravish Kumar | N32: Gavin Stead
A33: 5 | B33: RAKFLUX | D33: Internal | E33: NA | F33: NA | G33: NA | I33: Balaji Natarajan | J33: Sathiyan Venkatesh
A34: 5 | B34: Salary Application | C34: In Data Platform Scope | D34: Internal | E34: NA | F34: NA | G34: NA | I34: Gaurav Kumar | J34: Sathiyan Venkatesh | N34: Sumat Kumar
A35: 2 | B35: FX Rate Calculator | D35: Internal | I35: Mohammed Shoaib | J35: ?
A36: 3 | B36: DCR | D36: Internal | E36: NA | F36: NA | G36: NA | I36: Sree Rasmi Shaik Hussain Shariff | J36: Sathiyan Venkatesh | L36: Kanhai Kumar Jha | M36: Ravish Kumar | N36: Gavin Stead
A37: 2 | B37: Genesys/ EID/ UAEPASS | C37: External systems. Data can be fetched through API | D37: ThirdParty | E37: Al Futtaim | F37: Ghous Sayyed-External | G37: ghous.sayyed-external@alfuttaim.com | I37: Gaurav Kumar Mani John | J37: Sathiyan Venkatesh | N37: Sumat Kumar

Sheet Sheet2
E5: No. of fields | F5: CRM Source Systems List | G5: Vendor
E6: 1184 | F6: Finacle | G6: Infosys
E7: 335 | F7: Prime | G7: TSYS
E8: 197 | F8: WMS | G8: Infosys
E9: 190 | F9: RLS | G9: Nucleus Software
E10: 74 | F10: CASMEX | G10: Distinct Infotech
E11: 64 | F11: ICCS - Cheque Flow System | G11: NewGen technologies
E12: 48 | F12: Digital Banking Admin | G12: Infosys
E13: 41 | F13: Pay Hub Plus (NPSS Unity) | G13: Unity
E14: 33 | F14: CCM | G14: Dtech
E15: 27 | F15: MDES | G15: Master Card
E16: 24 | F16: RLS Collection | G16: Nucleus Software
E17: 22 | F17: Digital ON-Boarding Tracking (DEH) | G17: Infosys
... E23: 10 | F23: IBPS | G23: NewGen technologies

Sheet Remarks
A4: Application Type | B4: Remarks | C4: No. of fields | D4: *Systems List | E4: Approach | F4: Appln type | G4: Vendor | H4: Vendor Spoc | I4: Tech owner
A5: Third Party | B5: Procurement reached out | C5: 1184 | D5: Finacle | E5: In Data Platform Scope | F5: ThirdParty | G5: Infosys | H5: Amruta Anil Wadke | I5: Mani John
B6: Emailed on July 23rd | C6: 335 | D6: Prime | E6: In Data Platform Scope | F6: ThirdParty | G6: TSYS | H6: Mohamed Sukkari Muhammed Ajmal | I6: Sree Rasmi Shaik Hussain Shariff
B7: Procurement reached out | C7: 197 | D7: WMS | E7: In Data Platform Scope | F7: ThirdParty | G7: Infosys | H7: Aditya Kulkarni | I7: Mani John
B8: Emailed on July 25th | C8: 190 | D8: RLS | E8: In Data Platform Scope | F8: ThirdParty | G8: Nucleus Software | H8: Kaushal.misra@nucleussoftware.com | I8: Mani John
B9: Emailed on Jul 28th | C9: 74 | D9: CASMEX | E9: In Data Platform Scope | F9: ThirdParty | G9: Distinct Infotech | H9: rajeshkumar.rn@distinctinfotech.com chacko@distinctinfotech.com | I9: Guruprasad Narayan Shetty
B10: Emailed on Jul 28th | C10: 64 | D10: ICCS - Cheque Flow System | E10: In Data Platform Scope | F10: ThirdParty | G10: NewGen technologies | H10: Anshu Raj | I10: Guruprasad Narayan Shetty
B11: Procurement reached out | C11: 48 | D11: Digital Banking Admin | E11: In Data Platform Scope | F11: ThirdParty | G11: Infosys | H11: Amruta Anil Wadke | I11: Milind Harichandra Gowari
B12: Get confirmation from business | C12: 41 | D12: Pay Hub Plus (NPSS Unity) | F12: ThirdParty | G12: Unity | H12: Veena Vijayan | I12: Guruprasad Narayan Shetty
B13: Emailed on Jul 28th | C13: 33 | D13: CCM | F13: ThirdParty | G13: Dtech | H13: Muhammed Anees | I13: Mani John
B14: Contact to be provided by Procurement | C14: 27 | D14: MDES | F14: ThirdParty | G14: Not Identified
B15: Getting decommissioned. Need to refer intellect collection | C15: 24 | D15: RLS Collection | E15: In Data Platform Scope | F15: ThirdParty | G15: Nucleus Software | H15: Kaushal.misra@nucleussoftware.com | I15: Mani John
B16: Procurement reached out | C16: 22 | D16: Digital ON-Boarding Tracking (DEH) | E16: In Data Platform Scope | F16: ThirdParty | G16: Infosys | H16: Amruta Anil Wadke | I16: Milind Harichandra Gowari
B17: Contact to be provided by Procurement | C17: 16 | D17: VISA Online | F17: ThirdParty | G17: Not Identified
B18: Emailed on Jul 28th | C18: 16 | D18: RAKTRACK | F18: ThirdParty | G18: Game Change | H18: Shailesh Tiwari | I18: Mani John
B19: Get confirmation from business | C19: 14 | D19: 3D Secure | F19: ThirdParty/Internal | G19: Broadcom | H19: Konrad Karczmarczyk | I19: Guruprasad Narayan Shetty
B20: Contact to be provided by Procurement | C20: 13 | D20: Team Express Portal | F20: ThirdParty | G20: Not Identified
B21: Emailed on Jul 28th | C21: 11 | D21: Infobip | F21: ThirdParty | G21: Infobip | H21: Edita Rokša Durić <edita.roksaduric@infobip.com>; Neira Kratovac Akriche <neira.kratovacakriche@infobip.com>; Nedžad Grizović <nedzad.grizovic@infobip.com> | I21: Mani John
B22: Emailed on Jul 28th | C22: 10 | D22: IBPS | E22: In Data Platform Scope | F22: ThirdParty | G22: NewGen technologies | H22: Anshu Raj | I22: Gaurav Kumar
A23: Internal - CARDS platform | B23: ADO ticket created with CARDS platform - 400859 | C23: 20 | D23: CPPS | E23: In Data Platform Scope | F23: Internal | G23: CARDS Platform | H23: Sree Rasmi Shaik Hussai Sharif | I23: Gavin Stead
C24: 9 | D24: CardNet | F24: Internal
C25: 7 | D25: CAPS | E25: In Data Platform Scope | F25: Internal
C26: 3 | D26: DCR | F26: Internal
A27: Internal - Non cards applications | B27: Aligned Nilkanth and Sathiyan on Friday | C27: 73 | D27: IDD | F27: Internal | G27: Internal Applications | H27: Sathiyan Venkatesh | I27: Gaurav Kumar
C28: 48 | D28: Previous RAKNet Version (Personal Banking) | F28: Internal | I28: Gaurav Kumar
C29: 32 | D29: CPF | E29: In Data Platform Scope | F29: Internal | I29: Mani John
C30: 31 | D30: RAKRewards Admin | F30: Internal | I30: Gaurav Kumar
C31: 29 | D31: Bank Auth Representative E-Register(auth rep) | F31: Internal | I31: Gaurav Kumar
C32: 25 | D32: Cheque Book System | F32: Internal | I32: Gaurav Kumar
C33: 25 | D33: Cross Sell | F33: Internal | I33: Gaurav Kumar
C34: 10 | D34: Prospect | F34: Internal | I34: Gaurav Kumar
C35: 8 | D35: VAT | F35: Internal | I35: Gaurav Kumar
C36: 5 | D36: RAKFLUX | F36: Internal | I36: Balaji Natarajan
C37: 5 | D37: Salary Application | E37: In Data Platform Scope | F37: Internal | I37: Gaurav Kumar
C38: 14 | D38: 3D Secure | F38: Internal | I38: Guruprasad Narayan Shetty
C39: 2 | D39: FX Rate Calculator | F39: Internal | I39: Sunit Shetty

Sheet Status
N2: Isolated environment | O2: https://adb-4467010307787545.5.azuredatabricks.net/?o=4467010307787545
K3: source Type
A4: Tamanna comments | B4: Vendor | C4: *Systems List | D4: Milestone | E4: No. of fields | F4: No.of fields received | G4: Status | H4: Status as on Oct 20th | I4: Pending with | J4: RAG | K4: Integration Mechanism | L4: System Pipeline available | N4: IP UAT/Endpoint (Existing) | O4: UAT env (testing team) | P4: Business Owner | Q4: Technology Owner | R4: IP PROD | S4: IP DR | T4: DB Prod/Endpoint | U4: Peak CPU Utilization in Production Current | V4: Peak Memory Utilization | W4: DB name
A5: Have asked Mani | B5: Infosys | C5: Finacle | D5: M2,M3,M5,M7 | E5: 1184 | F5: 1069 | G5: In Progress | H5: Sep 19 - Received 834 fields as on 19/9. 341 to be shared. Alok reviewing the data. Oct 7 - 1069 data received - all 1to1 data fields | I5: Surabhi Alok Vendor | J5: Green | K5: Data Platform | L5: Yes | M5: ok | N5: 10.15.12.60, 5300 | O5: UAT2 | P5: Juzer Netterwala | Q5: Mani John | R5: 10.17.19.85/86:5300 | S5: 10.16.19.85/86:5300 | U5: 0.95 | V5: 0.6 | W5: Provided by source system team at field level
A6: Have asked Mani | B6: Infosys | C6: WMS | D6: M2, M6 | E6: 197 | F6: 118 | G6: In Progress | H6: Solution to be discussed for fields that has run time logical values Aditya - to clarify on fields marked as "Not applicable. Module is not licensed." Sep 26 - Surabhi scheduled meeting Oct 7 - BA followed up. NA items to be provided by vendor Discussion required on API development | I6: Dragos Vendor Alok, Surabhi | J6: Amber | K6: Data Platform + API? | L6: Yes | N6: 10.15.13.200,5301 | O6: UAT2 | P6: Rahul Gian Chandnani | Q6: Mani John | R6: 10.17.29.120/121:5310 | S6: 10.16.29.120:5310 | U6: 1 | V6: 0.65 | W6: Provided by source system team at field level
A7: Asked Milind | B7: Infosys | C7: Digital Banking Admin | D7: M2,M5,M7 | E7: 48 | F7: 46 | G7: In Progress | H7: 44 - database 2 fields - need API 2 fields - require BA inputs | I7: Surabhi Gopi Alok | J7: Green | K7: Data Platform + API? | L7: No | N7: CORP5 MCF Database IP: 10.15.25.6 Port: 5300 | O7: UAT2 | P7: Thomas Baxendale -Corporate Rahul Singh - Retail | Q7: Milind Harichandra Gowari | W7: Provided by source system team at field level
A8: Asked Milind | B8: Infosys | C8: Digital ON-Boarding Tracking (DEH) | D8: M5,M2 | E8: 22 | F8: 7 | G8: In Progress | H8: Front end code base is with Arjun's team Surabhi to clarify on fields requested from IBPS Surabhi scheduled meeting with vendor on Sep 26 Oct 13 - Business shared query. Alok to check on DEH tables Oct 13 - IBPS related fields to be provided by Business | I8: Alok Business | J8: Green | K8: Data Platform | L8: Yes | N8: server deh-db-dev-01.chgggpswwiss.me-central-1.rds.amazonaws.com:5500; 10.15.12.12:530 | P8: Sumat Kumar | Q8: Milind Harichandra Gowari Mani John | R8: 10.17.4.186/187:5300 | S8: 10.16.5.186/187:5300 | T8: deh-db-production-01.c9ma088winqb.me-central-1.rds.amazonaws.com : 5500 | U8: 0.7 | V8: 0.7 | W8: Provided by source system team at field level
A9: Have asked Sree | B9: TSYS | C9: Prime | D9: M2,M3, M5 | E9: 335 | F9: 0 | G9: Yet to Start | H9: Resourcing estimates shared by TSYS on Sep 25th. Sep 25 - PM emailed to Alfie to place WO and also included MDES in the scope to vendor Oct 13 - Awaiting VO/SoW from vendor | I9: Vendor | J9: Amber | K9: Data Platform? | L9: Yes | M9: ok | N9: 10.15.12.122, 5300 | O9: UAT2 | P9: Rehan Riaz Ahmad | Q9: Shaik Hussain Shariff | R9: 10.17.21.53/55:5300 | S9: 10.16.21.53/55:5300 | U9: NA | V9: NA | W9: Provided by source system team at field level
A10: Have asked Mani | B10: Nucleus | C10: RLS | D10: M2,M3,M5 | E10: 190 | F10: 149 | G10: In Progress | H10: Aug 12th - RLS is on-prem but DB access cannot be provided. Aug 13th - Discusses with RLS. Vendor agreed to provide DB details and come up with solution for other specs. Sent reminders on Sep 16, 25 Sep 26 - vendor confirmed the specs will be shared on or before Oct 7th - 149 fields provided only DB details. FE details not provided for any of 190 fields. Meeting scheduled on Oct 14th Oct 14 - Dragos to confirm on the calculated fields solution. Emailed | I10: Dragos Alok | J10: Amber | K10: Data Platform | L10: Yes | M10: ok | N10: 10.15.11.165:5300 | O10: UAT2 | P10: Shibani Mehra | Q10: Mani John | R10: 10.17.4.229:5300 | S10: 10.16.5.145:5300 | U10: 0.99 | V10: 0.99 | W10: Provided by source system team at field level
A11: Have asked Mani | B11: Intellect Design Arena | C11: Intellect Collection | D11: M2,M3,M5 | E11: 24 | F11: 0 | G11: Yet to start | H11: Sep 25 - Business Shared requirements from Intellect Surabhi reviewing pending 2 fields | I11: Business Surabhi | J11: Red | K11: Data Platform | L11: Yes | N11: Same DB as of RLS, app IP is different | O11: UAT2 | P11: Khadija Sultan Alhammadi | Q11: Mani John | W11: Provided by source system team at field level
A12: Have asked Devi | B12: Distinct Infotech | C12: CASMEX | D12: M2,M3 | E12: 74 | F12: 0 | G12: In Progress | H12: Had discussion with Vendor on Sep 1st. Vendor will share the detailes by EOD this month. Reminder sent on Sep 16 and 25 Sep 26 - vendor assured to provide specs asap. Oct 13 - PM sent followup | I12: Vendor | J12: Amber | K12: Data Platform | L12: Yes | N12: 10.15.13.97 & 5300 | O12: UAT2 | P12: Elcin Yanik | Q12: Guruprasad Narayan Shetty | R12: 10.17.4.147:5300 | S12: 10.16.4.90:5300 | U12: 0.65 | V12: 0.65 | W12: Provided by source system team at field level
A13: Have asked Guru | B13: NewGen | C13: ICCS - Cheque Flow System | D13: M2,M3 | E13: 64 | F13: 64 | G13: Completed | H13: Received on Aug 5th. | I13: Alok | J13: Completed | K13: Data Platform | L13: Yes | N13: 10.15.25.230; 5301 | O13: UAT2 | P13: Juzer Netterwala | Q13: Guruprasad Narayan Shetty | R13: 10.17.4.121:5301 | S13: 10.16.4.24:5301 | U13: NA | V13: NA | W13: Provided by source system team at field level
A14: Have asked Gaurav | B14: NewGen | C14: IBPS | D14: M5,M2 | E14: 10 | F14: 6 | G14: In Progress | H14: Received partially from Nikhil. Nikhil requested clarifications which Surabhi is addressing | I14: Surabhi | J14: Green | K14: Data Platform | L14: Yes | N14: 10.15.14.83:5301 | O14: UAT2 | P14: Juzer Netterwala | Q14: Gaurav Kumar | R14: 10.17.4.50:5301 | S14: 10.16.4.50:5301 | U14: NA | V14: NA | W14: Provided by source system team at field level
A15: Have asked Guru | B15: Unity | C15: Pay Hub Plus (NPSS Unity) | D15: M2,M3 | E15: 41 | F15: 0 | G15: Yet to Start | H15: To align with Payments team PM - Khutubuddin.Mohamed@rakbank.ae | I15: Surabhi | J15: Amber | K15: API | L15: No | P15: Elcin Yanik | Q15: Guruprasad Narayan Shetty | W15: Provided by source system team at field level
A16: Have asked Mani | B16: Dtech | C16: CCM | D16: M2,M5,M7 | E16: 33 | F16: 0 | G16: In Progress | H16: Had call with vendor on Jul 29th. Data ingestion possible. Anees suggesting to have DB view and proposing a solution that requires development effort. Call on Sep 23rd - Vendor team to come back with efforts. Some fields may not have one-to-one mapping DB type - Microsoft Sep 25 - Vendor confirmed to provide data by Oct 1st. SOW will be shared Oct 13 - PM requested for SoW and specs asap Oct 14 - SoW received. | I16: Vendor | J16: Green | K16: Data Platform | L16: No | N16: 10.15.13.125 | O16: Common env | P16: Sumat Kumar | Q16: Mani John | W16: Provided by source system team at field level
A17: Have asked Mani | B17: Game Change | C17: RAKTRACK | D17: M2,M5 | E17: 16 | F17: 14 | G17: In Progress | H17: Shailesh and Dragos discussed on 3 options. Shailesh team to assess these options and come with efforts and cost. RAKTRACK is on Mongo DB (non RDBMS), hence direct data ingestion will be a challenge though the app is onprem. 18.08 - Received front end specs for all 16 fields 18.09 - Confluent topic or API is proposed by vendor. Solution to be finalised by architects on 3 options Oct 6 - Solution finalised to go with Option 3 - API dev Oct 13 - PM emailed vendor for SoW and looped procurement | I17: Gopi/Dragos/Affan | J17: Red | K17: API | L17: No | N17: 10.15.13.246:5401 (DBA and Linux team unable to find this IP please confirm where is it hosted??) | O17: UAT2 | P17: Thomas Baxendale | Q17: Mani John | W17: Provided by source system team at field level
A18: Have asked Mani | B18: Infobip | C18: Infobip | D18: M2,M5 | E18: 11 | F18: 0 | G18: In Progress | H18: Solution discussion in progress with Infobip. Narek and Gopi discussing. We will be consuming details through API exposed to RAKBANK common platform. Frontend fields can be fetched from API details as well. Development of API - will be done by CRM. Ownership will be with Infobip support team - Mani John. Narek mentioned that Infobip will share their APIs for our dev to start | J18: Green | K18: API | L18: No | P18: Naya Kiochou | Q18: Mani John | W18: Provided by source system team at field level
A19: Have asked Sree | B19: MasterCard | C19: MDES (PRIME) | D19: M2,M3 | E19: 27 | F19: 0 | G19: Yet to Start | H19: Details can be taken from Cards systems per Ravish/Gopi. BA had call with CCO for business justification. BA to provide justification to Ravish . Sep 25 - PM included MDES in TSYS scope as Velan confirmed these details are from PRIME. Procurement to issue WO Sep 26 - PM emailed procurement team on establishing project with vendor | I19: Procurement | J19: Red | K19: API | L19: No | N19: Checked with Cards platform, this is not a system & it is only a token data stored in PRIME table. | O19: UAT2 | P19: Rehan Riaz Ahmad | Q19: Shaik Hussain Shariff | W19: Provided by source system team at field level
A20: Have asked Sree | B20: VISA | C20: VISA Online | D20: M2,M3 | E20: 16 | F20: 0 | G20: Yet to Start | H20: Sep 25 - Velan confirmed Visa tokenization is not working in production due to outdated interface flow. Surabhi to check with business on further steps Sep 26 - PM emailed procurement team on establishing project with vendor | I20: Procurement | J20: Red | K20: API | L20: No | N20: Checked with Cards platform, this is not a system & it is only a token data stored in PRIME table. | O20: UAT2 | P20: Rehan Riaz Ahmad | Q20: Shaik Hussain Shariff | W20: Provided by source system team at field level
A21: Have asked Sree | B21: Team Express | C21: Team Express Portal | D21: M5 | E21: 13 | F21: 13 | G21: Completed | H21: Scheduled meeting with Stalin. Team Express Portal can expose new API with required details. Data ingestion not possible. Budgeted development effort from the vendor. Front-end details to be provided by the vendor Front-End specs received Surabhi to confirm on milestone dates. Solution to be designed, Vendor to be aligned for dev efforts Not managed by IT Procurement. Mahesh to be contacted | I21: Surabhi Gopi | J21: Completed | K21: API | L21: No | P21: Shibani Mehra | Q21: Mahesh Kannan Kalarickel Gopalakrishnan ? | W21: Provided by source system team at field level
B22: ICC | C22: RAKRewards Admin | D22: M2,M3 | E22: 31 | F22: 0 | G22: Yet to Start | H22: Discussed with Badusha and Amit. This is new requirement for ICC and existing Digital banking APIs cannot be reused. Data cannot be ingested. 20.08 - Discussed with vendor - Detailed BRD on fields , API requested by vendor Surabhi to provide BRD | I22: Surabhi | J22: Green | K22: API | L22: No | P22: Rehan Riaz Ahmad | Q22: Mamta Peswani? | W22: Provided by source system team at field level
A23: Have asked Gaurav | B23: Pennanttech | C23: Cross Sell | D23: M2,M5 | E23: 25 | F23: 25 | G23: Completed | H23: All details received. In Data Platform scope. DB2 can provide only batch. Alternation solution to be provided by architect. Oct 9 - Solution confirmed by Gopi to go with API. Oct 13 - PM emailed vendor requesting API development efforts and looped procurement | I23: Vendor Procurement | J23: Amber | K23: API | L23: No | N23: 10.15.24.158 - 5302 (DB2 batch only possible) | O23: common env | P23: Himanshu Tyagi | Q23: Gaurav Kumar | W23: Provided by source system team at field level
A24: Have asked Sree | B24: Internal - CARDS | C24: CPPS | D24: M2,M3 | E24: 20 | F24: 20 | G24: Completed | H24: ADO ticket created with CARDS platform - 400859 Solution to be provided | I24: Gopi | J24: Completed | K24: API | L24: Yes | N24: 10.15.11.79:5322 (DB2 batch only possible) | O24: UAT1 | P24: Rehan Riaz Ahmad | Q24: Shaik Hussain Shariff | W24: Provided by source system team at field level
A25: Have asked Sree | B25: Internal - CARDS | C25: CAPS | D25: M2,M3 | E25: 7 | F25: 7 | G25: Completed | H25: ADO ticket created with CARDS platform - 400859. Gap analysis WIP | I25: Alok | J25: Completed | K25: Data Platform | L25: Yes | N25: 10.15.12.26:5310 | O25: UAT2 | P25: Rehan Riaz Ahmad | Q25: Shaik Hussain Shariff | R25: 10.17.4.97:5300 | S25: 10.16.5.154:5300 | U25: 0.98 | V25: 0.88 | W25: Provided by source system team at field level
A26: Have asked Sree | B26: Internal - CARDS | C26: DCR | D26: M2,M3,M5 | E26: 3 | F26: 3 | G26: Completed | H26: ADO ticket created with CARDS platform - 400859. Gap analysis WIP | I26: Alok | J26: Completed | K26: Data Platform | L26: No | N26: 10.15.12.26:5310 (DB IP is same, schema is different) | O26: UAT2 | P26: Elcin Yanik | Q26: Shaik Hussain Shariff | W26: Provided by source system team at field level
A27: Have asked Guru | B27: Internal | C27: CardNet | D27: M5 | E27: 9 | F27: 9 | G27: Completed | H27: Received from Sathiyan on Sep 12th. Solution to be provided | I27: Gopi | J27: Completed | K27: API | L27: No | P27: Rehan Riaz Ahmad | Q27: Guruprasad Narayan Shetty | W27: Provided by source system team at field level
A28: Have asked Gaurav | B28: Internal | C28: IDD | D28: M2,M6 | E28: 73 | F28: 73 | G28: Yet to Start | H28: Oct 6 - Received specs | I28: Sathiyan | J28: Completed | K28: API | L28: No | P28: Mohammed Ahmed Siddiqui | Q28: Gaurav Kumar | W28: Provided by source system team at field level
B29: Internal | C29: Previous RAKNet Version (Personal Banking) | D29: M2,M3,M5 | E29: 48 | F29: 0 | G29: Yet to Start | H29: Sathiyan searching for code base - legacy application | I29: Sathiyan | J29: Amber | K29: API? | L29: No | P29: ? | Q29: Gaurav Kumar | W29: Provided by source system team at field level
A30: Have asked Mani | B30: Internal | C30: CPF | D30: M2,M3,M7 | E30: 32 | F30: 32 | G30: Completed | H30: Oct 6 - Received specs | I30: Sathiyan | J30: Completed | K30: Data Platform | L30: Yes | N30: 10.15.12.194:5301 | O30: Common env | P30: Naya Kiochou | Q30: Mani John | W30: Provided by source system team at field level
A31: Have asked Gaurav | B31: Internal | C31: Bank Auth Representative E-Register(auth rep) | D31: M2,M3 | E31: 29 | F31: 0 | G31: Yet to Start | H31: Sathiyan searching for code base - legacy application | I31: Sathiyan | J31: Amber | K31: API? | L31: No | P31: Juzer Netterwala | Q31: Gaurav Kumar | W31: Provided by source system team at field level
A32: Have asked Gaurav | B32: Internal | C32: Cheque Book System | D32: M2,M3 | E32: 25 | F32: 25 | G32: Completed | H32: Received from Sathiyan on Sep 12th. Solution to be provided | I32: Gopi | J32: Completed | K32: API | L32: No | P32: Juzer Netterwala | Q32: Gaurav Kumar | W32: Provided by source system team at field level
A33: Have asked Guru | B33: Internal | C33: 3D Secure | D33: M2,M3, M5 | E33: 14 | F33: 14 | G33: Completed | H33: Received from Sathiyan on Sep 12th. Solution to be provided | I33: Gopi | J33: Completed | K33: API | L33: No | P33: Rehan Riaz Ahmad | Q33: Guruprasad Narayan Shetty | W33: Provided by source system team at field level
A34: Have asked Gaurav | B34: Internal | C34: Prospect | D34: M2,M5 | E34: 10 | F34: 10 | G34: Completed | H34: Received from Sathiyan on Aug 7th. Solution to be provided | I34: Gopi | J34: Completed | K34: API | L34: No | P34: Mona Ibrahim Al Shamsi | Q34: Gaurav Kumar | W34: Provided by source system team at field level
A35: Have asked Gaurav | B35: Internal | C35: VAT | D35: M5,M2 | E35: 8 | F35: 8 | G35: Completed | H35: Received from Sathiyan on Aug 7th. Solution to be provided | I35: Gopi | J35: Completed | K35: API | L35: No | P35: Manohar Bhoir | Q35: Gaurav Kumar | W35: Provided by source system team at field level
B36: Internal | C36: RAKFLUX | D36: M5 | E36: 5 | F36: 0 | G36: Yet to Start | H36: Sathiyan to prioritize the task. | I36: Sathiyan | J36: Green | K36: API | L36: No | W36: Provided by source system team at field level
A37: Have asked Gaurav | B37: Internal | C37: Salary Application | D37: M2,M3 | E37: 5 | F37: 5 | G37: Completed | H37: Received from Sathiyan on Sep 12th. Solution to be provided | I37: Gopi | J37: Completed | K37: API | L37: No | P37: Juzer Netterwala | Q37: Gaurav Kumar | W37: Provided by source system team at field level
A38: Have asked Mani | B38: Internal | C38: FX Rate Calculator | D38: M5,M2 | E38: 2 | F38: 2 | G38: Completed | H38: https://www.rakbank.ae/en/everyday-banking/send-pay/foreign-exchange-rates Data is required from this link. Its internal. Business -> Trade & Forex -> Forex Exchange rates will be fetched via API. Solution to be provided. Gopi to align with Manoj | I38: Gopi | J38: Completed | K38: API | L38: No | P38: Mohammad Ahteshamoddin | Q38: Mani John | W38: Provided by source system team at field level
B39: External | C39: Genesys | D39: M2, M7 | E39: 2 | F39: 2 | G39: Completed | H39: Authentication flag. To receive from API Solution signed-off by EDA. BRD to be issued to Genesys for SOW | I39: Surabhi | J39: Completed | K39: API | L39: No | P39: Mona Ibrahim Al Shamsi | Q39: Mani John | W39: Provided by source system team at field level
B40: External | C40: EID | E40: 2 | F40: 2 | G40: Completed | H40: Authentication flag. To receive from API Solution to be provided | I40: Gopi | J40: Completed | K40: API | L40: No | P40: Sumat Kumar | Q40: Gaurav
B41: External | C41: UAEPASS | E41: 2 | F41: 2 | G41: Completed | H41: Authentication flag. To receive from API Solution to be provided | I41: Gopi | J41: Completed | K41: API | L41: No | P41: -
...

Sheet Sheet3
B3: *Systems List | C3: Vendor | D3: Vendor Spoc | E3: Vendor contact | F3: Contact Phone
B4: Prime | C4: TSYS | D4: Mohamed Sukkari Muhammed Ajmal | E4: mohamedsukkari@tsys.com majmal@tsys.com
B5: RLS | C5: Nucleus Software | D5: Kaushal.misra@nucleussoftware.com | E5: Kaushal.misra@nucleussoftware.com
B6: CASMEX | C6: Distinct Infotech | D6: rajeshkumar.rn@distinctinfotech.com chacko@distinctinfotech.com | E6: rajeshkumar.rn@distinctinfotech.com chacko@distinctinfotech.com
B7: ICCS - Cheque Flow System | C7: NewGen technologies | D7: Anshu Raj | E7: anshu.raj@newgensoft.com
B8: CCM | C8: Dtech | D8: Muhammed Anees | E8: Muhammed.anees@dtechsoft.com
B9: MDES | C9: MASTERCARD
B10: RLS Collection | C10: Nucleus Software | D10: Kaushal.misra@nucleussoftware.com | E10: Kaushal.misra@nucleussoftware.com
B11: VISA Online | C11: VISA
B12: RAKTRACK | C12: Game Change | D12: Shailesh Tiwari | E12: shailesh.tiwari@gamechangesns.com
B13: 3D Secure | C13: Broadcom | D13: Konrad Karczmarczyk | E13: konrad.karczmarczyk@broadcom.com
B14: Team Express Portal | C14: Not Identified
B15: Infobip | C15: Infobip | D15: Edita Rokša Durić <edita.roksaduric@infobip.com>; Neira Kratovac Akriche <neira.kratovacakriche@infobip.com>; Nedžad Grizović <nedzad.grizovic@infobip.com> | E15: Edita Rokša Durić <edita.roksaduric@infobip.com>; Neira Kratovac Akriche <neira.kratovacakriche@infobip.com>; Nedžad Grizović <nedzad.grizovic@infobip.com>
B16: IBPS | C16: NewGen technologies | D16: Anshu Raj | E16: anshu.raj@newgensoft.com

Sheet M2
A1: Field Name | B1: CRM Section | C1: Core System | D1: Mapping
A2: Policy Number | B2: Basic Details | C2: IDD | D2: IDD -> Enquiry -> Policy Search -> Policy/ Proposal No.
A3: Product Name | B3: Basic Details | C3: IDD | D3: IDD -> Enquiry -> Policy Search -> Product Name
A4: Plan Name | B4: Basic Details | C4: IDD | D4: IDD -> Enquiry -> Policy Search -> Plan Name
A5: Policy Status | B5: Basic Details | C5: IDD | D5: IDD -> Enquiry -> Policy Search -> Policy Status
A6: Payment Frequency | B6: Policy Details | C6: IDD | D6: IDD -> Enquiry -> Policy Search -> Policy Details -> Policy Details -> Payment Frequency
A7: Policy Currency | B7: Basic Details | C7: IDD | D7: IDD -> Enquiry -> Policy Search -> Policy Details -> Policy Details -> Policy Currency
A8: Monthly Premium | B8: Policy Details | C8: IDD | D8: IDD -> Enquiry -> Policy Search -> Policy Details -> Policy Details -> M Premium
A9: Type | B9: Policy Details | C9: IDD | D9: IDD -> Enquiry -> Policy Search -> Policy Details -> Policy Details -> Type
A10: Plan Term (Years) | B10: Policy Details | C10: IDD | D10: IDD -> Enquiry -> Policy Search -> Policy Details -> Policy Details -> Plan Terms (Years)
A11: Total Premium
A12: Effective Policy Date | B12: Policy Details | C12: IDD | D12: IDD -> Enquiry -> Policy Search -> Policy Details -> Effective Policy Date

Sheet Approach
E2: Fileds/Logic received | G2: Fields yet to receive
B3: Vendor | C3: System | D3: No. of fields requested | E3: No. of static fields | F3: No. of runtime fields | G3: No. of static fields | H3: No. of runtime fields | I3: Is source DB internal to RAKBANK network ? | J3: Is System Pipeline available? | K3: Integration mechansim suggested by Architects | L3: Is API or IL development required from vendor/source team? | M3: Action with | N3: Action | O3: Remarks
A4: Oxygen, OF | B4: Infosys | C4: Finacle | D4: 1184 | E4: 1066 | F4: 0 | G4: 99 | H4: 19 | I4: Yes | J4: Yes | K4: Data Platform + API? | L4: Yes | M4: Alok | N4: Checking with vendor for logic | O4: Checking with vendor for logic
A5: Oxygen | B5: Infosys | C5: WMS | D5: 197 | E5: 117 | F5: 0 | G5: 47 | H5: 28 | I5: Yes | J5: Yes | K5: Data Platform + API? | L5: Yes | M5: Alok | N5: Checking with vendor for logic | O5: Checking with vendor for logic
B6: Infosys | C6: Digital Banking Admin | D6: 48 | E6: 44 | G6: 2 | H6: 2 | I6: Yes | J6: No | K6: Data Platform + API? | L6: Yes | M6: Alok | N6: Checking with vendor for logic | O6: Checking with vendor for logic
B7: Infosys | C7: Digital ON-Boarding Tracking (DEH) | D7: 8 | E7: 7 | F7: 0 | G7: 1 | H7: 0 | I7: Yes | J7: Yes | K7: Data Platform | L7: No | M7: Alok | N7: Alok to check with vendor for 1 field | O7: Alok to check with vendor for 1 field
A8: Oxygen, OF | B8: TSYS | C8: Prime | D8: 335 | E8: 0 | F8: 0 | G8: 0 | H8: 0 | I8: Yes | J8: Yes | K8: To be decided | L8: Maybe | M8: Keerthana | N8: PO in approval | O8: PO in approval
A9: Oxygen, OF | B9: Nucleus | C9: RLS | D9: 190 | E9: 149 | F9: 0 | G9: 0 | H9: 41 | I9: Yes | J9: Yes | K9: Data Platform | L9: Yes | M9: Dragos | N9: Dragos to confirm back to vendor on solution | O9: IL table dev required from vendor.
B10: Intellect Design Arena | C10: Intellect Collection | D10: 24 | E10: 0 | F10: 0 | G10: 0 | H10: 0 | I10: Yes | J10: Yes | K10: To be decided | L10: Maybe | M10: Surabhi | N10: Business to provide req | O10: Business to provide req
B11: Distinct Infotech | C11: CASMEX | D11: 74 | E11: 70 | F11: 0 | G11: 4 | H11: 0 | I11: Yes | J11: Yes | K11: Data Platform | L11: Maybe | M11: Alok | N11: Alok to check with vendor for 4 fields | O11: Alok to check with vendor for 4 fields
B12: NewGen | C12: ICCS - Cheque Flow System | D12: 64 | E12: 64 | F12: 0 | G12: 0 | H12: 0 | I12: Yes | J12: Yes | K12: Data Platform | L12: No | M12: DB team | N12: Data build to start | O12: No action
B13: NewGen | C13: IBPS | D13: 24 | E13: 6 | F13: 0 | G13: 18 | H13: 0 | I13: Yes | J13: Yes | K13: Data Platform | L13: No | M13: Surabhi | N13: Surabhi to check 18 fields with Nikhil | O13: Surabhi to check 18 fields with Nikhil
B14: Unity | C14: Pay Hub Plus (NPSS Unity) | D14: 41 | E14: 0 | F14: 0 | G14: 0 | H14: 0 | I14: Yes | J14: No | K14: Data Platform | L14: No | M14: Keerthana | N14: Keerthana to align with Unity PM | O14: Keerthana to align with Unity PM
B15: Dtech | C15: CCM | D15: 33 | E15: 0 | F15: 0 | G15: 0 | H15: 0 | I15: Yes | J15: No | K15: To be decided | L15: Maybe | M15: Keerthana | N15: PO in approval | O15: PO in approval
B16: Game Change | C16: RAKTRACK | D16: 16 | E16: NA | F16: NA | G16: NA | H16: NA | I16: Yes | J16: No | K16: API | L16: Yes | M16: Gopi | N16: Architect to provide tech requirement doc | O16: Mongo DB (Requires review). DB cannot connect
B17: Infobip | C17: Infobip | D17: 11 | E17: NA | F17: NA | G17: NA | H17: NA | I17: No | J17: No | K17: API | L17: Yes | M17: Narek | N17: Narek/Nedzad to develop API from vendor | O17: Infobip integration. External system
B18: MasterCard | C18: MDES | D18: 27 | E18: NA | F18: NA | G18: NA | H18: NA | I18: No | J18: No | K18: API | L18: Yes | M18: Gopi | N18: Architect to provide tech requirement doc | O18: External
B19: VISA | C19: VISA Online | D19: 16 | E19: NA | F19: NA | G19: NA | H19: NA | I19: No | J19: No | K19: API | L19: Yes | M19: Gopi | N19: Architect to provide tech requirement doc | O19: External
B20: Team Express | C20: Team Express Portal | D20: 13 | E20: NA | F20: NA | G20: NA | H20: NA | I20: No | J20: No | K20: API | L20: Yes | M20: Gopi | N20: Architect to provide tech requirement doc | O20: External
B21: ICC | C21: RAKRewards Admin | D21: 31 | E21: NA | F21: NA | G21: NA | H21: NA | I21: No | J21: No | K21: API | L21: Yes | M21: Surabhi/Gopi | N21: Surabhi to provide BRD. | O21: External
B22: Pennanttech | C22: Cross Sell | D22: 25 | E22: 25 | F22: 0 | G22: 0 | H22: 0 | I22: Yes | J22: No | K22: API | L22: Yes | M22: Gopi | N22: Architect to provide tech requirement doc | O22: DB2 (batch only possible)
B23: Internal - CARDS | C23: CPPS | D23: 20 | E23: 20 | F23: 0 | G23: 0 | H23: 0 | I23: Yes | J23: Yes | K23: API | L23: Yes | M23: Keerthana | N23: To align CARDS team for development | O23: DB2 (batch only possible)
B24: Internal - CARDS | C24: CAPS | D24: 7 | E24: 6 | F24: 1 | G24: 0 | H24: 0 | I24: Yes | J24: Yes | K24: Data Platform | L24: No | M24: Data team | N24: Data build to start | O24: 1 field logic to be redone
B25: Internal - CARDS | C25: DCR | D25: 3 | E25: NA | F25: NA | G25: NA | H25: NA | I25: Yes | J25: No | K25: API | L25: No | M25: Int. team | N25: Existing API to be used | O25: Existing API given by team
B26: Internal | C26: CardNet | D26: 9 | E26: 9 | F26: 0 | G26: 0 | H26: 0 | I26: Yes | J26: No | K26: API | L26: Yes | N26: To confirm the integration approach | O26: Legacy system
B27: Internal | C27: IDD | D27: 73 | E27: 73 | F27: 0 | G27: 0 | H27: 0 | I27: Yes | J27: No | K27: API | L27: Yes | N27: To confirm the integration approach | O27: Legacy system
B28: Internal | C28: Previous RAKNet Version (Personal Banking) | D28: 48 | E28: NA | F28: NA | G28: NA | H28: NA | I28: Yes | J28: No | K28: API | L28: Yes | N28: To confirm the integration approach | O28: Legacy system
B29: Internal | C29: CPF | D29: 32 | E29: 32 | F29: 0 | G29: 0 | H29: 0 | I29: Yes | J29: Yes | K29: Data Platform | L29: No | M29: Data team | N29: Data build to start
B30: Internal | C30: Bank Auth Representative E-Register(auth rep) | D30: 29 | E30: NA | F30: NA | G30: NA | H30: NA | I30: Yes | J30: No | K30: API | L30: Yes | N30: To confirm the integration approach | O30: Legacy system
B31: Internal | C31: Cheque Book System | D31: 25 | E31: 22 | F31: 0 | G31: 3 | H31: 0 | I31: Yes | J31: No | K31: API | L31: Yes | N31: To confirm the integration approach | O31: Legacy system
B32: Internal | C32: 3D Secure | D32: 14 | E32: 14 | F32: 0 | G32: 0 | H32: 0 | I32: Yes | J32: No | K32: API | L32: Yes | N32: To confirm the integration approach | O32: Legacy system
B33: Internal | C33: Prospect | D33: 10 | E33: 10 | F33: 0 | G33: 0 | H33: 0 | I33: Yes | J33: No | K33: API | L33: Yes | N33: To confirm the integration approach | O33: Legacy system
B34: Internal | C34: VAT | D34: 8 | E34: 4 | F34: 2 | G34: 2 | H34: 0 | I34: Yes | J34: No | K34: API | L34: Yes | N34: To confirm the integration approach | O34: Legacy system
B35: Internal | C35: RAKFLUX | D35: 5 | I35: Yes | J35: No | K35: API | L35: Yes | N35: To confirm the integration approach | O35: Legacy system
B36: Internal | C36: Salary Application | D36: 5 | E36: 5 | F36: 0 | G36: 0 | I36: Yes | J36: No | K36: API | L36: Yes | N36: To confirm the integration approach | O36: Legacy system
B37: Internal | C37: FX Rate Calculator | D37: 2 | E37: 0 | F37: 2 | I37: Yes | J37: No | K37: API | L37: Yes | N37: To confirm the integration approach | O37: Legacy system
B38: External | C38: Genesys | D38: 2 | E38: 0 | F38: 2 | I38: Yes | J38: No | K38: API | L38: Yes | N38: To confirm the integration approach | O38: Genesys integration
B39: External | C39: EID | D39: 2 | E39: 0 | F39: 2 | I39: Yes | J39: No | K39: API | L39: Yes | N39: To confirm the integration approach | O39: EIDA integration
B40: External | C40: UAEPASS | D40: 2 | E40: 0 | F40: 2 | I40: Yes | J40: No | K40: API | L40: Yes | N40: To confirm the integration approach | O40: UAEPASS integration
D41: =SUM(D4:D40) -> 2657 | E41: =SUM(E4:E40) -> 1743 | F41: =SUM(F4:F40) -> 11 | G41: =SUM(G4:G40) -> 176 | H41: =SUM(H4:H40) -> 90
...

Sheet SampleData
B3: Sample Required information –
B4: Type of Field (Frontend) | C4: Type of Field (Backend) | D4: Length (Frontend) | E4: Length (Backend) | F4: Format (Frontend) | G4: Format (Backend) | H4: List of Values (Frontend) | I4: List of Values (Backend) | J4: Can this data be fetched from DB or can be exposed via API? | K4: Database Name | L4: Table Name | M4: Database Field Name | N4: Any custom logic to populate this field
B5: dropdown | C5: dropdown | D5: 10 | E5: NVARCHAR(10 CHAR) | F5: String | G5: NVARCHAR2(10 CHAR) | H5: -FEMALE -MALE -NOT AVAILABLE | I5: -F -M -O
B6: Text | C6: Text | D6: 10 | E6: NVARCHAR(75) | F6: String | G6: NVARCHAR2(80 CHAR) | H6: NA | I6: NA

Sheet Sheet1
C3: Priority | D3: Application systems | E3: Description | F3: Technology Owner | G3: Technology Owner Manager | H3: Business Owner | I3: Business Owner Manager | J3: Vendor Spoc | K3: Vendor Contact
C4: 1 | D4: Finacle (Core Banking) | E4: Core Banking System | F4: Joy Sunil/ Mani John | G4: Sumat Kumar | H4: Chelliah Kumar | I4: Juzer Netterwala | J4: Yashpaul Jindal, Yashpaul.Jindal@infosys.com | K4: +971 565064530
J5: Vikram_Ansal@infosys.com
C6: 2 | D6: Islamic Banking(Flexcube) | E6: Islamic Banking System | F6: Manjit Kaur | G6: Sumat Kumar | H6: Shakeeb Inayatullah Isane/ Mani John | I6: Abdul Karim Juma | J6: Varghese Mathew , varghese.x.mathew@oracle.com | K6: +91 9986874212
J7: bikram.nanada@oracle.com
C8: 2 | D8: Front Arena (FIS) - Treasury | E8: Treasury Application | F8: Ruan Chapman | G8: Sumat Kumar | H8: Khushbu | I8: Vikas Suri | J8: Philip E, philip.hill@fisglobal.com | K8: Internal
C9: 3 | D9: FinOne- RLS | E9: Conventional Loan Management System | F9: Semeer Cherangathody | G9: Sumat Kumar | H9: Shibani , Divya, Archana , Abdullah Farooq | I9: Shibani Mehra | J9: Kaushal.misra@nucleussoftware.com | K9: +91 9810617822
E10: Loan originating System | G10: Sumat Kumar | H10: Abdullah Farooq / Roshan/ Archana | I10: Khadija Sultan Alhammadi
E11: Collection System is used for tracking bank collections and used by collection agents. | F11: Manjit Kaur | G11: Sumat Kumar | H11: Chelliah Kumar/ | I11: Shibani Mehra
C12: 4 | D12: PRIME4 | E12: Card Management system | F12: Shaik Hussain Shariff | G12: Sumat Kumar | I12: Rehan Riaz Ahmad | J12: majmal@tsys.com | K12: +971 50 2100680
J13: mohamedsukkari@tsys.com
C14: 4 | D14: CAPS | E14: (Provision of Loan System) | F14: Sijina, Vijayalakshmi (Viji), Anuj Agarwal | G14: Sumat Kumar | H14: Saurabh Kumar Sharma | I14: Sumeet Vijay Jain | J14: Sree Rasmi Sasikumaran <Sree.Sasikumaran@rakbank.ae> | K14: Internal
H15: Farzan Dalal
C16: 5 | D16: EximBills | E16: Trade Finance Application | F16: Deshika Mani | G16: Sumat Kumar | H16: Chelliah Kumar/Balaji Viswalingam / Hemalika | I16: Vikas Suri | J16: Thushara@chinasystems-me.com
J17: Antony-antony@chinasystems-me.com
C18: 6 | D18: MAPS | E18: Retail Banking | F18: Hadrain Fernando | G18: Sumat Kumar | H18: Shaik Hussain Shariff | I18: Rajesh Sharma/Sonia Gregory/ | J18: Rahul Mehta - rahul.mehta@isgdigitalfirst.com
J19: Praveen Balusu - praveenb@insolutionsglobal.com
C20: 7 | D20: ALM (Fund Transfer Pricing-Asset Management Liability) | E20: Fund transfer pricing Asset Liabilities Mgmt | F20: Charu Saumya/ KRM Support | G20: Sumat Kumar | I20: Mridul Ashok Baberwal | J20: KamakuraAspacTeam@sas.com | K20: +886 919361377
J21: WeiBo.Kao@sas.com
C22: 8 | D22: CASMEX | E22: Remittance Processing System | F22: Guruprasad Narayan Shetty/ Jonathan/Hadrian Fernando | G22: Sumat Kumar | H22: Ashutosh/Rahul/Manoj | J22: rajeshkumar.rn@distinctinfotech.com, chacko@distinctinfotech.com
C23: 9 | D23: Kiplot -Project Portfolio System | E23: Project Portfolio System | F23: Steeve | G23: Samil Salim | H23: Steeve | I23: Samil Salim | J23: Balpreet Rihal - balpreet.rihal@kiplot.com

Sheet Summary
A2: Vendor | B2: System | C2: Milestone | D2: No. of fields requested | E2: Integration mechansim suggested by Architects | F2: Milestone 1 tables | G2: Milestone 2 tables | H2: Milestone 3 tables | I2: Milestone 4 tables | J2: Milestone 5 tables | K2: Milestone 6 tables | L2: Milestone 7 tables | M2: Milestone 8 tables
A3: Infosys | B3: Finacle | C3: M1, M2, M3, M4, M5, M6, M7, M8 | D3: 1202 | E3: Data Platform + API | F3: accounts, corporate, ENTITYDOCUMENT, Person, PhoneEmail, categories, category_lang Incidents | G3: Accounts, agent_entity_details, bizcenter, Corporate, DEMOGRAPHIC, ENTITY_INTEREST_TABLE, ENTITYDOCUMENT, EXTN_BODATA , GENERAL_ACCT_MAST_TABLE, MiscellaneousInfo, Person, PhoneEmail, SBCA_MAST_TABLE, TD_ACCT_MASTER_TABLE, | H3: ACCT_AUTH_SIGN_TABLE, Accounts, Address, agent_entity_details, ACH_PAYSYS_REASON_TABLE, ACCT_STATEMENT_TABLE, bizcenter, CUST_LDFEE, CUST_PAYGEN_ORD_TABLE, C_PORD_REMIT_INR, C_PORDM_DELETE, C_REJECT CMB_CSIS_GEN_ACCT_TABLE, CNMA, Corporate, CUST_CALBK, DEMOGRAPHIC, DAILY_TRAN_DETAIL_TABLE, ENTITY_INTEREST_TABLE, ENTITYDOCUMENT, entityrelationship, GEN_ACCT_MAST_MOD_TABLE, GEN_ACCT_CLASS_TABLE, GENERAL_ACCT_MAST_TABLE, SOL_GROUP_CONTROL_TABLE, GEN_SCHM_PARM_TABLE, LOGIN_TABLE, memberships, MiscellaneousInfo, ML_MMSG_TBL, MEMO_PAD_TABLE, OPERATIONSREASONCODES, Person, PhoneEmail, PAYMENT_ORDER_DETAIL_TABLE, PAYMENT_ORDER_HEADER_TABLE, preferences, psychographic, SWIFT_MSG_HISTORY_TABLE, SBCA_MAST_TABLE, SERVICE_OUTLET_TABLE, users, | I3: accounts, ACCT_AUTH_SIGN_TABLE, ADM, ALH, ALT, AST, C_CPVALUE, C_CRDT, CBT, CNC, corporate, DTD, EIT, entityrelationship, EXTN_BODATA , FinancialDetails, GAC, GAM, GSP, Incidents, ITC, PFT, Request, RSTD, SIH, TAM, TBA_RENEWAL_OPTION_TBL, TBA_TD_ACCT_MASTER_TBL, TDT, TSD
A4: Infosys | B4: WMS | C4: M2, M3, M7 | D4: 159 | E4: Data Platform + API | F4: WIGDT | G4: WIGDT | H4: WIGDT
A5: Infosys | B5: Digital Banking Admin | C5: M1, M2, M3, M4 | D5: 48 | E5: Data Platform + API | F5: CORPORATE_USER, MULTI_LEVEL_WORKFLOW_TABLE | G5: CORPORATE_USER
A6: Infosys | B6: Digital ON-Boarding Tracking (DEH) | C6: M1, M3, M5, M7, M8 | D6: 8 | E6: Data Platform
A7: TSYS | B7: Prime | C7: M1, M2, M3, M4 | D7: 305 | E7: Data Platform + API | F7: ILCARDX, People | G7: ILCARDEMBOSSING, ILCARDX, ILCACCOUNTS, lILCURRENCIES, ILPRODUCTS, ILCARDSTATUS, ILCSTATEMENTS PEOPLE ILISSUER_AUTHORIZATIONS iltbalances | H7: ILCINSTALMENTS Cinstalmentamortization ILACPLINKS ILACPROFILES ILAPPLOG ILBATCHES lILCURRENCIES ilcaccounts ILCACCOUNTSTMT ILCADDRESSES ILCARDEMBOSSING ILCARDS ILCARDSTATUS ILCARDX ILCCUSTOMERS ILCEXTENSION ILCSTATEMENTS ILCISOTRXNS ILCTRANSACTIONS ILCURRENCIES ILTRXNSTATUS ILGLOBALPARAMETERVALUES ILGLOBALPARAMETERS ILGROUPS ILINSTALMENTPLANS ILISSUER_AUTHORIZATIONS ILMEMOS ILMEMOTYPES ILPRODUCTS ILPROFILES ilTrxntypes iltBalances ilarchtBalances
A8: Nucleus | B8: RLS | C8: M1, M2, M3, M4, M5, M6 | D8: 190 | E8: Data Platform (batch) | F8: lea_agreement_dtl NBFC_CUSTOMER_M LEA_APPL_DTL | G8: LEA_AGREEMENT_DTL LEA_APPL_DTL LEA_REPAYSCH_DTL NBFC_CUSTOMER_M | H8: lea_agreement_dtl NBFC_CUSTOMER_M LEA_APPL_DTL
A9: Nucleus | B9: RLS collection | C9: M2, M4, M5 | D9: 24 | E9: Data Platform
A10: Distinct Infotech | B10: CASMEX | C10: M3, M5 | D10: 74 | E10: Data Platform | H10: DX_TRNS_REMITTANCE DX_REF_ACTIVITY_LOG | I10: DX_TRNS_REMITTANCE DX_REF_ACTIVITY_LOG
A11: NewGen | B11: ICCS - Cheque Flow System | C11: M3 | D11: 64 | E11: Data Platform | H11: Outward_ICCS ICCS_TAB_RoutingNumbers Inward_Ext_Tab
A12: NewGen | B12: IBPS | C12: M1, M2, M3, M4 | D12: 24 | E12: Data Platform | F12: wfinstrumenttable RB_PC_EXTTABLE RB_CMS_EXTTABLE RB_ML_EXTTABLE RB_DAC_EXTTABLE RB_BSR_EXTTABLE RB_iRBL_EXTTABLE RB_CSR_BT_EXTTABLE RB_CSR_CCB_EXTTABLE RB_CSR_CCC_EXTTABLE RB_CSR_MISC_EXTTABLE RB_CSR_OCC_EXTTABLE RB_CSR_RR_EXTTABLE RB_DSR_DCB_EXTTABLE RB_DSR_MISC_EXTTABLE RB_DSR_ODC_EXTTABLE RB_GSR_LCOL_EXTTABLE RB_ODDD_EXTTABLE RB_DA_Exttable RB_TF_EXTTABLE RB_SRB_EXTTABLE RB_AO_EXTTABLE RB_SRM_EXTTABLE RB_EPP_EXTTABLE RB_SAR_EXTTABLE RB_BAIS_EXTTABLE NG_DCC_EXTTABLE NG_DAO_EXTTABLE NG_TT_EXT_TABLE RB_TL_EXTTABLE RB_SRO_EXTTABLE RB_OECD_EXTTABLE RB_TWC_EXTTABLE RB_CU_EXTTABLE NG_DPL_EXTTABLE RB_DBO_EXTTABLE RB_CMS_EXTTABLE NG_TS_EXTTABLE RB_NBTL_EXTTABLE NG_EIBOR_EXTTABLE ng_CourtOrder_exttable RB_KYC_REM_EXTTABLE RB_DBS_EXTTABLE RB_PL_EXTTABLE | H12: wfinstrumenttable
A13: Unity | B13: Pay Hub Plus (NPSS Unity) | C13: M3, M4 | D13: 41 | E13: Data Platform | H13: NPSS_PaymentsStatusConfig NPSS_PmtStatus_ReqHdr NPSS_RTPaymentsDtl_Inw NPSS_RTPaymentsDtl_InwExn NPSS_RTPaymentsDtl_Out NPSS_RTPaymentsDtl_OutExn NPSS_RTPaymentsHdr_Inw NPSS_RTPaymentsHdr_Out NPSS_RTS_PmtStatusDtl_Dbtr
A14: Dtech | B14: CCM | C14: M2, M4, M5 | D14: 33 | E14: Data Platform | G14: DeliveryRegistration
A15: Infobip | B15: Infobip | C15: M3, M4 | D15: 11 | E15: Data Platform
A16: Internal - CARDS | B16: CPPS | C16: M4 | D16: 20 | E16: Data Platform (batch)
A17: Internal - CARDS | B17: CAPS | C17: M3, M6 | D17: 7 | E17: Data Platform (batch) | H17: CARD_GENERAL CARDS
A18: Internal - CARDS | B18: DCR (take from PRIME) | C18: - | D18: 3 | E18: Data Platform
A19: Internal | B19: CPF | C19: M1, M2, M3, M7 | D19: 32 | E19: Data Platform | G19: customer_consent customer_info consent_configs | H19: customer_consent customer_info consent_configs customer_consent_audit
A20: Internal | B20: 3D Secure (take from Infobip) | C20: M4 | D20: 14 | E20: Data Platform

Sheet DataIngestion-SQL
A1: Finacle | H1: Prime | O1: WMS | V1: Digital Banking Admin | AC1: Digital ON-Boarding Tracking (DEH) | AJ1: RLS | AQ1: RLS collection (RLS) | AX1: CASMEX | BE1: ICCS - Cheque Flow System | BL1: IBPS | BS1: Pay Hub Plus (NPSS Unity) | BZ1: CCM | CG1: Infobip | CN1: CPPS | CU1: CAPS | DB1: DCR (from PRIME) | DI1: CPF | DP1: 3D secure (from Infobip)
A2: Milestone | B2: Source table name | C2: CRM ODS table name | D2: Transactional table? If Y, one yr historical datato be loaded (rolling time) Purging to be implemented | E2: Data ingestion CRM_DEV from UAT2 | F2: Data ingestion CRM_SIT from UAT2 | G2: Data ingestion CRM_UAT from UAT2 | H2: Milestone | I2: Source table name | J2: CRM ODS table name | K2: Transactional table? If Y, one yr historical datato be loaded (rolling time) Purging to be implemented | L2: Data ingestion CRM_DEV | M2: Data ingestion CRM_SIT | N2: Data ingestion CRM_UAT | O2: Milestone | P2: Source table name | Q2: CRM ODS table name | R2: Transactional table? If Y, one yr historical datato be loaded (rolling time) Purging to be implemented | S2: Data ingestion CRM_DEV | T2: Data ingestion CRM_SIT | U2: Data ingestion CRM_UAT | V2: Milestone | W2: Source table name | X2: CRM ODS table name | Y2: Transactional table? If Y, one yr historical datato be loaded (rolling time) Purging to be implemented | Z2: Data ingestion CRM_DEV | AA2: Data ingestion CRM_SIT | AB2: Data ingestion CRM_UAT | AC2: Milestone | AD2: Source table name | AE2: CRM ODS table name | AF2: Transactional table? If Y, one yr historical datato be loaded (rolling time) Purging to be implemented | AG2: Data ingestion CRM_DEV | AH2: Data ingestion CRM_SIT | AI2: Data ingestion CRM_UAT | AJ2: Milestone | AK2: Source table name | AL2: CRM ODS table name | AM2: Transactional table? If Y, one yr historical datato be loaded (rolling time) Purging to be implemented | AN2: Data ingestion CRM_DEV | AO2: Data ingestion CRM_SIT | AP2: Data ingestion CRM_UAT | AQ2: Milestone | AR2: Source table name | AS2: CRM ODS table name | AT2: Transactional table? If Y, one yr historical datato be loaded (rolling time) Purging to be implemented | AU2: Data ingestion CRM_DEV | AV2: Data ingestion CRM_SIT | AW2: Data ingestion CRM_UAT | AX2: Milestone | AY2: Source table name | AZ2: CRM ODS table name | BA2: Transactional table? If Y, one yr historical datato be loaded (rolling time) Purging to be implemented | BB2: Data ingestion CRM_DEV | BC2: Data ingestion CRM_SIT | BD2: Data ingestion CRM_UAT | BE2: Milestone | BF2: Source table name | BG2: CRM ODS table name | BH2: Transactional table? If Y, one yr historical datato be loaded (rolling time) Purging to be implemented | BI2: Data ingestion CRM_DEV | BJ2: Data ingestion CRM_SIT | BK2: Data ingestion CRM_UAT | BL2: Milestone | BM2: Source table name | BN2: CRM ODS table name | BO2: Transactional table? If Y, one yr historical datato be loaded (rolling time) Purging to be implemented | BP2: Data ingestion CRM_DEV | BQ2: Data ingestion CRM_SIT | BR2: Data ingestion CRM_UAT | BS2: Milestone | BT2: Source table name | BU2: CRM ODS table name | BV2: Transactional table? If Y, one yr historical datato be loaded (rolling time) Purging to be implemented | BW2: Data ingestion CRM_DEV | BX2: Data ingestion CRM_SIT | BY2: Data ingestion CRM_UAT | BZ2: Milestone | CA2: Source table name | CB2: CRM ODS table name | CC2: Transactional table? If Y, one yr historical datato be loaded (rolling time) Purging to be implemented | CD2: Data ingestion CRM_DEV | CE2: Data ingestion CRM_SIT | CF2: Data ingestion CRM_UAT | CG2: Milestone | CH2: Source table name | CI2: CRM ODS table name | CJ2: Transactional table? If Y, one yr historical datato be loaded (rolling time) Purging to be implemented | CK2: Data ingestion CRM_DEV | CL2: Data ingestion CRM_SIT | CM2: Data ingestion CRM_UAT | CN2: Milestone | CO2: Source table name | CP2: CRM ODS table name | CQ2: Transactional table? If Y, one yr historical datato be loaded (rolling time) Purging to be implemented | CR2: Data ingestion CRM_DEV | CS2: Data ingestion CRM_SIT | CT2: Data ingestion CRM_UAT | CU2: Milestone | CV2: Source table name | CW2: CRM ODS table name | CX2: Transactional table? If Y, one yr historical datato be loaded (rolling time) Purging to be implemented | CY2: Data ingestion CRM_DEV | CZ2: Data ingestion CRM_SIT | DA2: Data ingestion CRM_UAT | DB2: Milestone | DC2: Source table name | DD2: CRM ODS table name | DE2: Transactional table? If Y, one yr historical datato be loaded (rolling time) Purging to be implemented | DF2: Data ingestion CRM_DEV | DG2: Data ingestion CRM_SIT | DH2: Data ingestion CRM_UAT | DI2: Milestone | DJ2: Source table name | DK2: CRM ODS table name | DL2: Transactional table? If Y, one yr historical datato be loaded (rolling time) Purging to be implemented | DM2: Data ingestion CRM_DEV | DN2: Data ingestion CRM_SIT | DO2: Data ingestion CRM_UAT | DP2: Milestone | DQ2: Source table name | DR2: CRM ODS table name | DS2: Transactional table? If Y, one yr historical datato be loaded (rolling time) Purging to be implemented | DT2: Data ingestion CRM_DEV | DU2: Data ingestion CRM_SIT | DV2: Data ingestion CRM_UAT
A3: Milestone 1 | B3: accounts | C3: CRM_DEV.finacle.CRMUSER_ACCOUNTS | E3: 46387 | H3: Milestone 1 | I3: ILCARDX | J3: CRM_DEV.prime4.TCTDBS_CARDX | O3: Milestone 1 | P3: WMS_INV_GEN_DTLS_TBL | Q3: 46035 | S3: 46035 | T3: 46035 | V3: Milestone1 | W3: CORPORATE_USER | Z3: 46038 | AJ3: Milestone1 | AK3: LEA_AGREEMENT_DTL | AL3: CRM_DEV.rls.FIN_LEAM_LEA_AGREEMENT_DTL | AX3: Milestone 3 | AY3: DX_TRNS_REMITTANCE | BE3: Milestone3 | BF3: Outward_ICCS | BL3: Milestone1 | BM3: wfinstrumenttable | BS3: Milestone3 | BT3: NPSS_PaymentsStatusConfig | BZ3: Milestone 2 | CA3: DeliveryRegistration | CU3: Milestone3 | CV3: CARD_GENERAL | CW3: CRM_DEV.caps.CAPSADMIN_CARD_GENERAL | DI3: Milestone2 | DJ3: customer_consent
A4: Milestone 1 | B4: corporate | C4: CRM_DEV.finacle.CRMUSER_CORPORATE | E4: 46387 | H4: Milestone 1 | I4: PEOPLE | J4: CRM_DEV.prime4.TCTDBS_PEOPLE | L4: 46030 | O4: Milestone 2 | P4: WMS_INV_GEN_DTLS_TBL | V4: Milestone1 | W4: MULTI_LEVEL_WORKFLOW_TABLE | AJ4: Milestone1 | AK4: NBFC_CUSTOMER_M | AX4: Milestone 3 | AY4: DX_REF_ACTIVITY_LOG | BE4: Milestone3 | BF4: ICCS_TAB_RoutingNumbers | BL4: Milestone1 | BM4: RB_PC_EXTTABLE | BS4: Milestone3 | BT4: NPSS_PmtStatus_ReqHdr | CU4: Milestone3 | CV4: CARDS | CW4: CRM_DEV.caps.CAPSADMIN_CARDS | DI4: Milestone2 | DJ4: customer_info
A5: Milestone 1 | B5: ENTITYDOCUMENT | C5: CRM_DEV.finacle.CRMUSER_ENTITYDOCUMENT | H5: Milestone 2 | I5: ILCARDEMBOSSING | J5: TCTDBS_CARDEMBOSSING | O5: Milestone 3 | P5: WMS_INV_GEN_DTLS_TBL | V5: Milestone2 | W5: CORPORATE_USER | AJ5: Milestone1 | AK5: LEA_APPL_DTL | AL5: CRM_DEV.rls.FIN_LEAM_LEA_APPL_DTL | AX5: Milestone 4 | AY5: DX_TRNS_REMITTANCE | BE5: Milestone3 | BF5: Inward_Ext_Tab | BL5: Milestone1 | BM5: RB_CMS_EXTTABLE | BS5: Milestone3 | BT5: NPSS_RTPaymentsDtl_Inw | DI5: Milestone2 | DJ5: consent_configs
A6: Milestone 1 | B6: Person | C6: CRM_DEV.finacle.CRMUSER_PERSON | E6: 46387 | H6: Milestone 2 | I6: ILCARDX | J6: CRM_DEV.prime4.TCTDBS_CARDX | AJ6: Milestone2 | AK6: LEA_AGREEMENT_DTL | AL6: CRM_DEV.rls.FIN_LEAM_LEA_AGREEMENT_DTL | AX6: Milestone 4 | AY6: DX_REF_ACTIVITY_LOG | BL6: Milestone1 | BM6: RB_ML_EXTTABLE | BS6: Milestone3 | BT6: NPSS_RTPaymentsDtl_InwExn | DI6: Milestone3 | DJ6: customer_consent
A7: Milestone 1 | B7: PhoneEmail | C7: CRM_DEV.finacle.CRMUSER_PHONEEMAIL | H7: Milestone 2 | I7: ILCACCOUNTS | J7: CRM_DEV.prime4.TCTDBS_CACCOUNTS | L7: 46030 | AJ7: Milestone2 | AK7: LEA_APPL_DTL | AL7: CRM_DEV.rls.FIN_LEAM_LEA_APPL_DTL | BL7: Milestone1 | BM7: RB_DAC_EXTTABLE | BS7: Milestone3 | BT7: NPSS_RTPaymentsDtl_Out | DI7: Milestone3 | DJ7: customer_info
A8: Milestone 1 | B8: categories | C8: CRM_DEV.finacle.CRMUSER_CATEGORIES | E8: 46024 | H8: Milestone 2 | I8: ILCURRENCIES | J8: CRM_DEV.prime4.TCTDBS_CURRENCIES | AJ8: Milestone2 | AK8: LEA_REPAYSCH_DTL | AL8: CRM_DEV.rls.FIN_LEAM_LEA_REPAYSCH_DTL | BL8: Milestone1 | BM8: RB_BSR_EXTTABLE | BS8: Milestone3 | BT8: NPSS_RTPaymentsDtl_OutExn | DI8: Milestone3 | DJ8: consent_configs
